Workbook

Sheet Продажи Ozon
A1: Дата | B1: Order ID | C1: SKU | D1: Кол-во, шт | E1: Цена реализации, ₽ | F1: Тип оплаты | G1: Refund
A2: 2026-04-01 | B2: OZ-100000024 | C2: ABC-CLN-042 | D2: 109 | E2: 380 | F2: Ozon Pay | G2: N
A3: 2026-04-01 | B3: OZ-100000061 | C3: ABC-CLN-042 | D3: 437 | E3: 380 | F3: Карта | G3: N
A4: 2026-04-01 | B4: OZ-100001826 | C4: ABC-LDR-034 | D4: 158 | E4: 720 | F4: Карта | G4: N
A5: 2026-04-01 | B5: OZ-100001864 | C5: ABC-LDR-034 | D5: 39 | E5: 720 | F5: Ozon Pay | G5: N
A6: 2026-04-01 | B6: OZ-100003878 | C6: ABC-LDR-027 | D6: 159 | E6: 290 | F6: Карта | G6: N
A7: 2026-04-01 | B7: OZ-100003924 | C7: ABC-LDR-027 | D7: 40 | E7: 290 | F7: Ozon Pay | G7: N
A8: 2026-04-01 | B8: OZ-100003945 | C8: ABC-LDR-027 | D8: 66 | E8: 290 | F8: Wallet | G8: N
A9: 2026-04-01 | B9: OZ-100006001 | C9: ABC-DSH-018 | D9: 436 | E9: 216 | F9: Карта | G9: N
A10: 2026-04-01 | B10: OZ-100006019 | C10: ABC-DSH-018 | D10: 109 | E10: 216 | F10: Ozon Pay | G10: N
A11: 2026-04-01 | B11: OZ-100006034 | C11: ABC-DSH-018 | D11: 182 | E11: 216 | F11: Wallet | G11: N
A12: 2026-04-01 | B12: OZ-100007773 | C12: ABC-KIT-051 | D12: 212 | E12: 350 | F12: Wallet | G12: N
A13: 2026-04-01 | B13: OZ-100009883 | C13: ABC-WND-009 | D13: 73 | E13: 220 | F13: Wallet | G13: N
... A403: 2026-04-30 | B403: OZ-100011861 | C403: ABC-WND-009 | D403: -97 | E403: 176 | F403: Карта | G403: Y

Sheet Продажи WB
A1: Дата | B1: Order ID | C1: Артикул | D1: Наименование | E1: Кол-во, шт | F1: Цена реализации, ₽ | G1: Тип оплаты | H1: Refund
A2: 2026-04-01 | B2: WB-200000029 | C2: ABC-CLN-042 | D2: Средство для пола 1л | E2: 214 | F2: 380 | G2: Wallet | H2: N
A3: 2026-04-01 | B3: WB-200000047 | C3: ABC-CLN-042 | D3: Средство для пола 1л | E3: 129 | F3: 380 | G3: Ozon Pay | H3: N
A4: 2026-04-01 | B4: WB-200001504 | C4: ABC-LDR-034 | D4: Детский гель для стирки 1.5л | E4: 128 | F4: 720 | G4: Ozon Pay | H4: N
A5: 2026-04-01 | B5: WB-200002920 | C5: ABC-LDR-027 | D5: Кондиционер для белья 1л | E5: 164 | F5: 290 | G5: Wallet | H5: N
A6: 2026-04-01 | B6: WB-200004453 | C6: ABC-DSH-018 | D6: Средство для посуды 500мл | E6: 263 | F6: 240 | G6: Ozon Pay | H6: N
A7: 2026-04-01 | B7: WB-200006128 | D7: Чистящий крем кухня 750 мл | E7: 145 | F7: 350 | G7: Ozon Pay | H7: N
A8: 2026-04-01 | B8: WB-200007619 | C8: WND-009 | D8: Очиститель стёкол 500мл | E8: 194 | F8: 220 | G8: Карта | H8: N
A9: 2026-04-02 | B9: WB-200000064 | C9: ABC-CLN-042 | D9: Средство для пола 1л | E9: 101 | F9: 380 | G9: Wallet | H9: N
A10: 2026-04-02 | B10: WB-200000107 | C10: ABC-CLN-042 | D10: Средство для пола 1л | E10: 242 | F10: 380 | G10: Карта | H10: N
A11: 2026-04-02 | B11: WB-200001520 | C11: ABC-LDR-034 | D11: Детский гель для стирки 1.5л | E11: 128 | F11: 720 | G11: Карта | H11: N
A12: 2026-04-02 | B12: WB-200002967 | C12: ABC-LDR-027 | D12: Кондиционер для белья 1л | E12: 164 | F12: 290 | G12: Карта | H12: N
A13: 2026-04-02 | B13: WB-200004474 | C13: ABC-DSH-018 | D13: Средство для посуды 500мл | E13: 395 | F13: 216 | G13: Wallet | H13: N
A14: 2026-04-02 | B14: WB-200006154 | D14: Чистящий крем кухня 750 мл | E14: 145 | F14: 350 | G14: Ozon Pay | H14: N
A15: 2026-04-02 | B15: WB-200007648 | C15: WND-009 | D15: Очиститель стёкол 500мл | E15: 194 | F15: 220 | G15: Карта | H15: N
A16: 2026-04-03 | B16: WB-200000138 | C16: ABC-CLN-042 | D16: Средство для пола 1л | E16: 343 | F16: 380 | G16: Карта | H16: N
A17: 2026-04-03 | B17: WB-200001556 | C17: ABC-LDR-034 | D17: Детский гель для стирки 1.5л | E17: 128 | F17: 720 | G17: Ozon Pay | H17: N
A18: 2026-04-03 | B18: WB-200003010 | C18: ABC-LDR-027 | D18: Кондиционер для белья 1л | E18: 116 | F18: 290 | G18: Карта | H18: N
A19: 2026-04-03 | B19: WB-200003056 | C19: ABC-LDR-027 | D19: Кондиционер для белья 1л | E19: 48 | F19: 290 | G19: Wallet | H19: N
A20: 2026-04-03 | B20: WB-200004517 | C20: ABC-DSH-018 | D20: Средство для посуды 500мл | E20: 395 | F20: 216 | G20: Wallet | H20: N
A21: 2026-04-03 | B21: WB-200006181 | D21: Чистящий крем кухня 750 мл | E21: 116 | F21: 350 | G21: Карта | H21: N
A22: 2026-04-03 | B22: WB-200006222 | D22: Чистящий крем кухня 750 мл | E22: 29 | F22: 350 | G22: Ozon Pay | H22: N
A23: 2026-04-03 | B23: WB-200007671 | C23: WND-009 | D23: Очиститель стёкол 500мл | E23: 155 | F23: 220 | G23: Карта | H23: N
A24: 2026-04-03 | B24: WB-200007697 | C24: WND-009 | D24: Очиститель стёкол 500мл | E24: 39 | F24: 220 | G24: Ozon Pay | H24: N
A25: 2026-04-04 | B25: WB-200000153 | C25: ABC-CLN-042 | D25: Средство для пола 1л | E25: 343 | F25: 380 | G25: Wallet | H25: N
A26: 2026-04-04 | B26: WB-200001602 | C26: ABC-LDR-034 | D26: Детский гель для стирки 1.5л | E26: 80 | F26: 720 | G26: Wallet | H26: N
A27: 2026-04-04 | B27: WB-200001639 | C27: ABC-LDR-034 | D27: Детский гель для стирки 1.5л | E27: 48 | F27: 720 | G27: Ozon Pay | H27: N
A28: 2026-04-04 | B28: WB-200003087 | C28: ABC-LDR-027 | D28: Кондиционер для белья 1л | E28: 164 | F28: 290 | G28: Wallet | H28: N
A29: 2026-04-04 | B29: WB-200004549 | C29: ABC-DSH-018 | D29: Средство для посуды 500мл | E29: 247 | F29: 216 | G29: Wallet | H29: N
A30: 2026-04-04 | B30: WB-200004594 | C30: ABC-DSH-018 | D30: Средство для посуды 500мл | E30: 148 | F30: 216 | G30: Ozon Pay | H30: N
A31: 2026-04-04 | B31: WB-200006269 | D31: Чистящий крем кухня 750 мл | E31: 145 | F31: 350 | G31: Карта | H31: N
A32: 2026-04-04 | B32: WB-200007743 | C32: WND-009 | D32: Очиститель стёкол 500мл | E32: 194 | F32: 220 | G32: Карта | H32: N
A33: 2026-04-05 | B33: WB-200000183 | C33: ABC-CLN-042 | D33: Средство для пола 1л | E33: 343 | F33: 380 | G33: Карта | H33: N
A34: 2026-04-05 | B34: WB-200001677 | C34: ABC-LDR-034 | D34: Детский гель для стирки 1.5л | E34: 128 | F34: 720 | G34: Ozon Pay | H34: N
A35: 2026-04-05 | B35: WB-200003110 | C35: ABC-LDR-027 | D35: Кондиционер для белья 1л | E35: 131 | F35: 290 | G35: Карта | H35: N
A36: 2026-04-05 | B36: WB-200003129 | C36: ABC-LDR-027 | D36: Кондиционер для белья 1л | E36: 33 | F36: 290 | G36: Ozon Pay | H36: N
A37: 2026-04-05 | B37: WB-200004631 | C37: ABC-DSH-018 | D37: Средство для посуды 500мл | E37: 116 | F37: 216 | G37: Wallet | H37: N
A38: 2026-04-05 | B38: WB-200004660 | C38: ABC-DSH-018 | D38: Средство для посуды 500мл | E38: 279 | F38: 216 | G38: Карта | H38: N
A39: 2026-04-05 | B39: WB-200006302 | D39: Чистящий крем кухня 750 мл | E39: 145 | F39: 350 | G39: Карта | H39: N
A40: 2026-04-05 | B40: WB-200007769 | C40: WND-009 | D40: Очиститель стёкол 500мл | E40: 155 | F40: 220 | G40: Карта | H40: N
...

Sheet Производство
A1: Дата производства | B1: Партия № | C1: SKU | D1: Наименование | E1: Кол-во, шт | F1: Себестоимость партии, ₽ | G1: Себестоимость, ₽/шт
A2: 2026-03-29 | B2: П-24001 | C2: ABC-CLN-042 | D2: Средство для пола 1л | E2: 8600 | F2: 968790 | G2: 112.65
A3: 2026-04-17 | B3: П-24002 | C3: ABC-CLN-042 | D3: Средство для пола 1л | E3: 11500 | F3: 1270750 | G3: 110.5
A4: 2026-04-19 | B4: П-24003 | C4: ABC-CLN-042 | D4: Средство для пола 1л | E4: 10900 | F4: 1209900 | G4: 111
A5: 2026-03-26 | B5: П-24004 | C5: ABC-LDR-034 | D5: Детский гель для стирки 1.5л | E5: 2800 | F5: 629300 | G5: 224.75
A6: 2026-04-02 | B6: П-24005 | C6: ABC-LDR-034 | D6: Детский гель для стирки 1.5л | E6: 3500 | F6: 785505 | G6: 224.43
A7: 2026-04-13 | B7: П-24006 | C7: ABC-LDR-034 | D7: Детский гель для стирки 1.5л | E7: 4500 | F7: 982035 | G7: 218.23
A8: 2026-03-28 | B8: П-24007 | C8: ABC-LDR-027 | D8: Кондиционер для белья 1л | E8: 2400 | F8: 241848 | G8: 100.77
A9: 2026-03-29 | B9: П-24008 | C9: ABC-LDR-027 | D9: Кондиционер для белья 1л | E9: 2800 | F9: 304220 | G9: 108.65
A10: 2026-03-30 | B10: П-24009 | C10: ABC-LDR-027 | D10: Кондиционер для белья 1л | E10: 1400 | F10: 148526 | G10: 106.09
A11: 2026-04-02 | B11: П-24010 | C11: ABC-LDR-027 | D11: Кондиционер для белья 1л | E11: 2800 | F11: 303016 | G11: 108.22
A12: 2026-04-06 | B12: П-24011 | C12: ABC-LDR-027 | D12: Кондиционер для белья 1л | E12: 2600 | F12: 279266 | G12: 107.41
A13: 2026-04-08 | B13: П-24012 | C13: ABC-LDR-027 | D13: Кондиционер для белья 1л | E13: 2000 | F13: 210760 | G13: 105.38
... A27: 2026-04-04 | B27: П-24026 | C27: ABC-WND-009 | D27: Очиститель стёкол 500мл | E27: 6100 | F27: 467443 | G27: 76.63

Sheet Транспорт
A1: Дата | B1: Накладная № | C1: Перевозчик | D1: Направление | E1: Сумма без НДС, ₽ | F1: НДС, ₽
A2: 2026-04-01 | B2: ТТН-14502 | C2: ООО Логистик-Экспресс | D2: FBO Ozon Электросталь | E2: 30060 | F2: 6012
A3: 2026-04-01 | B3: ТТН-14520 | C3: ТК ПЭК | D3: FBO Ozon Тверь | E3: 17029 | F3: 3406
A4: 2026-04-02 | B4: ТТН-14508 | C4: ТК Деловые Линии | D4: FBO Ozon Тверь | E4: 18158 | F4: 3632
A5: 2026-04-05 | B5: ТТН-14505 | C5: ООО Логистик-Экспресс | D5: FBO WB Подольск | E5: 23491 | F5: 4698
A6: 2026-04-05 | B6: ТТН-14512 | C6: ООО Авто-Перевозки | D6: FBO Ozon Электросталь | E6: 17600 | F6: 3520
A7: 2026-04-06 | B7: ТТН-14504 | C7: ТК ПЭК | D7: FBO WB Казань | E7: 24000 | F7: 4800
A8: 2026-04-06 | B8: ТТН-14507 | C8: ТК Деловые Линии | D8: FBO Ozon Электросталь | E8: 29106 | F8: 5821
A9: 2026-04-12 | B9: ТТН-14501 | C9: ООО Логистик-Экспресс | D9: FBO Ozon Тверь | E9: 25933 | F9: 5187
A10: 2026-04-14 | B10: ТТН-14516 | C10: ООО Логистик-Экспресс | D10: FBO Ozon Электросталь | E10: 33052 | F10: 6610
A11: 2026-04-19 | B11: ТТН-14510 | C11: ООО Логистик-Экспресс | D11: Прочее (склад) | E11: 35825 | F11: 7165
A12: 2026-04-19 | B12: ТТН-14513 | C12: ООО Логистик-Экспресс | D12: FBO WB Подольск | E12: 37595 | F12: 7519
A13: 2026-04-20 | B13: ТТН-14509 | C13: ИП Скоробогатов А.С. | D13: FBO Ozon Тверь | E13: 27616 | F13: 5523
... A23: 2026-04-28 | B23: ТТН-14503 | C23: ТК ПЭК | D23: FBO Ozon Электросталь | E23: 30497 | F23: 6099

Sheet Соинвест Ozon
A1: Дата начала | B1: Дата конца | C1: SKU | D1: Наименование | E1: % баллов
A2: 46113 | B2: 46126 | C2: ABC-CLN-042 | D2: Средство для пола 1л | E2: 0.015
A3: 46127 | B3: 46142 | C3: ABC-CLN-042 | D3: Средство для пола 1л | E3: 0.025
A4: 46113 | B4: 46127 | C4: ABC-LDR-034 | D4: Детский гель для стирки 1.5л | E4: 0.005
A5: 46128 | B5: 46142 | C5: ABC-LDR-034 | D5: Детский гель для стирки 1.5л | E5: 0.015
A6: 46113 | B6: 46122 | C6: ABC-LDR-027 | D6: Кондиционер для белья 1л | E6: 0.01
A7: 46123 | B7: 46137 | C7: ABC-LDR-027 | D7: Кондиционер для белья 1л | E7: 0.025
A8: 46138 | B8: 46142 | C8: ABC-LDR-027 | D8: Кондиционер для белья 1л | E8: 0.015
A9: 46113 | B9: 46142 | C9: ABC-DSH-018 | D9: Средство для посуды 500мл | E9: 0.01
A10: 46113 | B10: 46122 | C10: ABC-KIT-051 | D10: Чистящий крем кухня 750мл | E10: 0.015
A11: 46123 | B11: 46142 | C11: ABC-KIT-051 | D11: Чистящий крем кухня 750мл | E11: 0.025
A12: 46113 | B12: 46117 | C12: ABC-WND-009 | D12: Очиститель стёкол 500мл | E12: 0.06
A13: 46118 | B13: 46137 | C13: ABC-WND-009 | D13: Очиститель стёкол 500мл | E13: 0.09
A14: 46138 | B14: 46142 | C14: ABC-WND-009 | D14: Очиститель стёкол 500мл | E14: 0.06

Sheet Реклама Ozon
A1: Дата | B1: Кампания | C1: SKU | D1: Расход, ₽ | E1: Показы | F1: Клики | G1: Заказы
A2: 2026-04-01 | B2: Кондиционер-Поиск | C2: ABC-LDR-027 | D2: 8956 | E2: 153737 | F2: 5102 | G2: 393
A3: 2026-04-01 | B3: Пол-апрель-Карточка | C3: ABC-CLN-042 | D3: 7226 | E3: 128216 | F3: 4072 | G3: 120
A4: 2026-04-01 | B4: Пол-апрель-Поиск | C4: ABC-CLN-042 | D4: 14313 | E4: 190044 | F4: 9289 | G4: 707
A5: 2026-04-02 | B5: Кондиционер-Поиск | C5: ABC-LDR-027 | D5: 9742 | E5: 163871 | F5: 4158 | G5: 302
A6: 2026-04-02 | B6: Кухня-крем-Поиск | C6: ABC-KIT-051 | D6: 5041 | E6: 48594 | F6: 1349 | G6: 87
A7: 2026-04-02 | B7: Пол-апрель-Карточка | C7: ABC-CLN-042 | D7: 7367 | E7: 75612 | F7: 2475 | G7: 165
A8: 2026-04-02 | B8: Пол-апрель-Поиск | C8: ABC-CLN-042 | D8: 10421 | E8: 91113 | F8: 3755 | G8: 198
A9: 2026-04-02 | B9: Посуда-апрель-Карточка | C9: ABC-DSH-018 | D9: 4736 | E9: 56764 | F9: 2165 | G9: 57
A10: 2026-04-02 | B10: Посуда-апрель-Поиск | C10: ABC-DSH-018 | D10: 3045 | E10: 50129 | F10: 1892 | G10: 61
A11: 2026-04-02 | B11: Стирка-детский-Категория | C11: ABC-LDR-034 | D11: 7543 | E11: 109380 | F11: 5262 | G11: 322
A12: 2026-04-02 | B12: Стирка-детский-Поиск | C12: ABC-LDR-034 | D12: 4570 | E12: 50961 | F12: 1389 | G12: 42
A13: 2026-04-02 | B13: Стёкла-Карточка | C13: ABC-WND-009 | D13: 1886 | E13: 28215 | F13: 722 | G13: 37
... A246: 2026-04-30 | B246: Стёкла-Поиск | C246: ABC-WND-009 | D246: 1283 | E246: 14679 | F246: 497 | G246: 26

Sheet Реклама WB
A1: Дата | B1: Кампания | C1: SKU | D1: Расход, ₽ | E1: Показы | F1: Клики | G1: Заказы
A2: 2026-04-01 | B2: WB-Пол-Авто | C2: ABC-CLN-042 | D2: 8767 | E2: 116011 | F2: 3198 | G2: 248
A3: 2026-04-01 | B3: WB-Посуда-Авто | C3: ABC-DSH-018 | D3: 6700 | E3: 80372 | F3: 1867 | G3: 145
A4: 2026-04-01 | B4: WB-Стирка-детский-Авто | C4: ABC-LDR-034 | D4: 12510 | E4: 138569 | F4: 5050 | G4: 323
A5: 2026-04-01 | B5: WB-Стёкла-Авто | C5: ABC-WND-009 | D5: 1561 | E5: 23753 | F5: 1146 | G5: 82
A6: 2026-04-01 | B6: WB-Стёкла-Каталог | C6: ABC-WND-009 | D6: 2226 | E6: 37990 | F6: 1182 | G6: 69
A7: 2026-04-02 | B7: WB-Кондиционер-Авто | C7: ABC-LDR-027 | D7: 3193 | E7: 44073 | F7: 662 | G7: 30
A8: 2026-04-02 | B8: WB-Кухня-Авто | C8: ABC-KIT-051 | D8: 5997 | E8: 77409 | F8: 1894 | G8: 45
A9: 2026-04-02 | B9: WB-Пол-Авто | C9: ABC-CLN-042 | D9: 7007 | E9: 82274 | F9: 3214 | G9: 180
A10: 2026-04-02 | B10: WB-Посуда-Авто | C10: ABC-DSH-018 | D10: 5624 | E10: 89280 | F10: 2395 | G10: 70
A11: 2026-04-02 | B11: WB-Стирка-детский-Авто | C11: ABC-LDR-034 | D11: 6920 | E11: 95479 | F11: 2345 | G11: 168
A12: 2026-04-03 | B12: WB-Пол-Авто | C12: ABC-CLN-042 | D12: 11699 | E12: 182726 | F12: 4267 | G12: 301
A13: 2026-04-03 | B13: WB-Стирка-детский-Авто | C13: ABC-LDR-034 | D13: 10141 | E13: 138218 | F13: 3731 | G13: 86
... A135: 2026-04-30 | B135: WB-Стёкла-Каталог | C135: ABC-WND-009 | D135: -1265 | E135: 43549 | F135: 876 | G135: 27

Sheet Тарифы Ozon
A1: SKU | B1: Наименование | C1: Категория Ozon | D1: Комиссия, % | E1: Логистика, ₽/шт
A2: ABC-CLN-042 | B2: Средство для пола 1л | C2: Бытхимия | D2: 0.27 | E2: 35
A3: ABC-LDR-034 | B3: Детский гель для стирки 1.5л | C3: Бытхимия | D3: 0.27 | E3: 60
A4: ABC-LDR-027 | B4: Кондиционер для белья 1л | C4: Бытхимия | D4: 0.27 | E4: 40
A5: ABC-DSH-018 | B5: Средство для посуды 500мл | C5: Посуда | D5: 0.27 | E5: 25
A6: ABC-KIT-051 | B6: Чистящий крем кухня 750мл | C6: Посуда | D6: 0.27 | E6: 35
A7: ABC-WND-009 | B7: Очиститель стёкол 500мл | C7: Стёкла | D7: 0.27 | E7: 35

Sheet Тарифы WB
A1: SKU | B1: Наименование | C1: Категория WB | D1: Комиссия, % | E1: Логистика, ₽/шт
A2: ABC-CLN-042 | B2: Средство для пола 1л | C2: Бытхимия | D2: 0.295 | E2: 47.25
A3: ABC-LDR-034 | B3: Детский гель для стирки 1.5л | C3: Бытхимия | D3: 0.295 | E3: 81
A4: ABC-LDR-027 | B4: Кондиционер для белья 1л | C4: Бытхимия | D4: 0.295 | E4: 54
A5: ABC-DSH-018 | B5: Средство для посуды 500мл | C5: Посуда | D5: 0.295 | E5: 33.75
A6: ABC-KIT-051 | B6: Чистящий крем кухня 750мл | C6: Посуда | D6: 0.295 | E6: 47.25
A7: ABC-WND-009 | B7: Очиститель стёкол 500мл | C7: Стёкла | D7: 0.295 | E7: 47.25

Sheet Счета бренд-рекламы
A1: Дата | B1: Номер счёта | C1: Контрагент | D1: Категория | E1: Сумма, ₽ | F1: Статус
A2: 2026-04-04 | B2: С-18002 | C2: ООО ПромоПринт | D2: Прочее | E2: 15000 | F2: Оплачено
A3: 2026-04-05 | B3: С-18009 | C3: ООО Перформанс Креатив | D3: Стирка | E3: 70000 | F3: Оплачено
A4: 2026-04-07 | B4: С-18006 | C4: ООО ТВ-Креатив | D4: Кухня | E4: 60000 | F4: Оплачено
A5: 2026-04-08 | B5: С-18003 | C5: ООО Видео-Студия Окно | D5: Стирка | E5: 180000 | F5: Оплачено
A6: 2026-04-11 | B6: С-18011 | C6: ИП Сидоров А.И. (баннеры) | D6: Стёкла | E6: 50000 | F6: Оплачено
A7: 2026-04-14 | B7: С-18007 | C7: ИП Сидоров А.И. (баннеры) | D7: Посуда | E7: 40000 | F7: Оплачено
A8: 2026-04-16 | B8: С-18008 | C8: ИП Соколова Е.В. (соцсети) | D8: Пол | E8: 70000 | F8: Оплачено
A9: 2026-04-17 | B9: С-18004 | C9: ООО Видео-Студия Окно | D9: Пол | E9: 130000 | F9: Оплачено
A10: 2026-04-17 | B10: С-18005 | C10: ИП Иванов (продакшн) | D10: Стирка | E10: 100000 | F10: Оплачено
A11: 2026-04-18 | B11: С-18010 | C11: ООО Перформанс Креатив | D11: Посуда | E11: 60000 | F11: Оплачено
A12: 2026-04-26 | B12: С-18001 | C12: ООО Бренд-Бюро | D12: Прочее | E12: 25000 | F12: Оплачено

Sheet Зарплатная ведомость
A1: ФИО | B1: Должность | C1: Отдел | D1: Оклад, ₽ | E1: Бонус, ₽ | F1: Налоги работодателя, ₽ | G1: ИТОГО ФОТ, ₽
A2: Иванов Алексей Петрович | B2: Генеральный директор | C2: Управление | D2: 410000 | E2: 60000 | F2: 141940 | G2: 611940
A3: Соколова Мария Сергеевна | B3: Финансовый директор | C3: Управление | D3: 270000 | E3: 35000 | F3: 92110 | G3: 397110
A4: Петров Никита Андреевич | B4: Руководитель Ozon | C4: Маркетплейсы | D4: 170000 | E4: 35000 | F4: 61910 | G4: 266910
A5: Орлова Анна Викторовна | B5: Руководитель WB | C5: Маркетплейсы | D5: 150000 | E5: 25000 | F5: 52850 | G5: 227850
A6: Кузнецова Юлия Игоревна | B6: Менеджер Ozon | C6: Маркетплейсы | D6: 95000 | E6: 10000 | F6: 31710 | G6: 136710
A7: Лебедев Михаил Сергеевич | B7: Менеджер WB | C7: Маркетплейсы | D7: 85000 | E7: 10000 | F7: 28690 | G7: 123690
A8: Новиков Артур Сергеевич | B8: Менеджер по закупкам | C8: Маркетплейсы | D8: 95000 | E8: 10000 | F8: 31710 | G8: 136710
A9: Морозов Дмитрий Олегович | B9: Руководитель маркетинга | C9: Маркетинг | D9: 150000 | E9: 25000 | F9: 52850 | G9: 227850
A10: Васильева Елена Михайловна | B10: Маркетолог-аналитик | C10: Маркетинг | D10: 95000 | E10: 5000 | F10: 30200 | G10: 130200
A11: Сидоров Артём Иванович | B11: Дизайнер | C11: Маркетинг | D11: 90000 | E11: 5000 | F11: 28690 | G11: 123690
A12: Григорьева Ольга Андреевна | B12: Контент-менеджер | C12: Маркетинг | D12: 75000 | E12: 5000 | F12: 24160 | G12: 104160
A13: Смирнов Игорь Васильевич | B13: Начальник склада | C13: Склад | D13: 105000 | E13: 10000 | F13: 34730 | G13: 149730
... A16: Григорьев Павел Александрович | B16: Бухгалтер | C16: Бухгалтерия | D16: 75000 | E16: 5000 | F16: 24160 | G16: 104160

Sheet Прочие постоянные
A1: Дата | B1: Номер счёта | C1: Контрагент | D1: Статья | E1: Сумма, ₽
A2: 2026-04-01 | B2: СЧ-22011 | C2: ООО Связь-Москва | D2: Прочие административные | E2: 89540
A3: 2026-04-04 | B3: СЧ-22015 | C3: 1С: Партнёр Регион | D3: IT-услуги | E3: 89750
A4: 2026-04-05 | B4: СЧ-22014 | C4: WB Партнёры подписка | D4: IT-услуги | E4: 30410
A5: 2026-04-08 | B5: СЧ-22004 | C5: ООО Канцторг | D5: Прочие административные | E5: 49990
A6: 2026-04-08 | B6: СЧ-22012 | C6: Командировки | D6: Прочие административные | E6: 109900
A7: 2026-04-10 | B7: СЧ-22007 | C7: Сбербанк (РКО + комиссии) | D7: Прочие административные | E7: 179250
A8: 2026-04-12 | B8: СЧ-22009 | C8: ИП Логистик-Партнёр | D8: Прочие услуги | E8: 121840
A9: 2026-04-13 | B9: СЧ-22010 | C9: ООО ЧистоКлин | D9: Прочие услуги | E9: 79850
A10: 2026-04-17 | B10: СЧ-22003 | C10: ООО Хостинг Северо-Запад | D10: IT-услуги | E10: 55320
A11: 2026-04-18 | B11: СЧ-22002 | C11: Расходные материалы | D11: Прочие административные | E11: 71320
A12: 2026-04-19 | B12: СЧ-22008 | C12: ООО Складские решения | D12: Аренда | E12: 1000000
A13: 2026-04-20 | B13: СЧ-22006 | C13: Юристъ-консалт ИП | D13: Прочие услуги | E13: 119990
... A16: 2026-04-28 | B16: СЧ-22005 | C16: Bitrix24 | D16: IT-услуги | E16: 44530

Sheet Источники
A1: SKU | B1: Канал | C1: Категория | D1: Объём | E1: Выручка валовая, ₽ | F1: Возврат, ₽ | G1: Чистая выручка, ₽ | H1: Себестоимость, ₽ | I1: Комиссия, ₽ | J1: Логистика, ₽ | K1: Эквайринг (в комиссии), ₽ | L1: ДРР, ₽ | M1: Соинвест, ₽
A2: ABC-CLN-042 | B2: Ozon | C2: Бытхимия | D2: =SUMIFS('Продажи Ozon'!$D:$D, 'Продажи Ozon'!$C:$C, "ABC-CLN-042", 'Продажи Ozon'!$G:$G, "N") | E2: =ROUND(SUMPRODUCT(('Продажи Ozon'!$C$2:$C$2000="ABC-CLN-042") * ('Продажи Ozon'!$G$2:$G$2000="N") * 'Продажи Ozon'!$D$2:$D$2000 * 'Продажи Ozon'!$E$2:$E$2000),2) | F2: =ROUND(-SUMPRODUCT(('Продажи Ozon'!$C$2:$C$2000="ABC-CLN-042") * ('Продажи Ozon'!$G$2:$G$2000="Y") * 'Продажи Ozon'!$D$2:$D$2000 * 'Продажи Ozon'!$E$2:$E$2000),2) | G2: =E2-F2 | H2: =ROUND(D2 * SUMPRODUCT(('Производство'!$C$2:$C$2000="ABC-CLN-042") * 'Производство'!$E$2:$E$2000 * 'Производство'!$G$2:$G$2000) / SUMIFS('Производство'!$E:$E, 'Производство'!$C:$C, "ABC-CLN-042"),2) | I2: =ROUND(G2 * VLOOKUP("ABC-CLN-042", 'Тарифы Ozon'!$A:$E, 4, FALSE),2) | J2: =ROUND(D2 * VLOOKUP("ABC-CLN-042", 'Тарифы Ozon'!$A:$E, 5, FALSE),2) | K2: 0 | L2: =ROUND(SUMIFS('Реклама Ozon'!$D:$D, 'Реклама Ozon'!$C:$C, "ABC-CLN-042"),2) | M2: =ROUND(G2 * SUMPRODUCT(('Соинвест Ozon'!$C$2:$C$100="ABC-CLN-042") * 'Соинвест Ozon'!$E$2:$E$100 * ('Соинвест Ozon'!$B$2:$B$100-'Соинвест Ozon'!$A$2:$A$100+1)) / SUMPRODUCT(('Соинвест Ozon'!$C$2:$C$100="ABC-CLN-042") * ('Соинвест Ozon'!$B$2:$B$100-'Соинвест Ozon'!$A$2:$A$100+1)),2)
A3: ABC-CLN-042 | B3: WB | C3: Бытхимия | D3: =SUMIFS('Продажи WB'!$E:$E, 'Продажи WB'!$C:$C, "ABC-CLN-042", 'Продажи WB'!$H:$H, "N") | E3: =ROUND(SUMPRODUCT(('Продажи WB'!$C$2:$C$2000="ABC-CLN-042") * ('Продажи WB'!$H$2:$H$2000="N") * 'Продажи WB'!$E$2:$E$2000 * 'Продажи WB'!$F$2:$F$2000),2) | F3: =ROUND(-SUMPRODUCT(('Продажи WB'!$C$2:$C$2000="ABC-CLN-042") * ('Продажи WB'!$H$2:$H$2000="Y") * 'Продажи WB'!$E$2:$E$2000 * 'Продажи WB'!$F$2:$F$2000),2) | G3: =E3-F3 | H3: =ROUND(D3 * SUMPRODUCT(('Производство'!$C$2:$C$2000="ABC-CLN-042") * 'Производство'!$E$2:$E$2000 * 'Производство'!$G$2:$G$2000) / SUMIFS('Производство'!$E:$E, 'Производство'!$C:$C, "ABC-CLN-042"),2) | I3: =ROUND(G3 * VLOOKUP("ABC-CLN-042", 'Тарифы WB'!$A:$E, 4, FALSE),2) | J3: =ROUND(D3 * VLOOKUP("ABC-CLN-042", 'Тарифы WB'!$A:$E, 5, FALSE),2) | K3: 0 | L3: =ROUND(SUMIFS('Реклама WB'!$D:$D, 'Реклама WB'!$C:$C, "ABC-CLN-042"),2) | M3: 0
A4: ABC-LDR-034 | B4: Ozon | C4: Бытхимия | D4: =SUMIFS('Продажи Ozon'!$D:$D, 'Продажи Ozon'!$C:$C, "ABC-LDR-034", 'Продажи Ozon'!$G:$G, "N") | E4: =ROUND(SUMPRODUCT(('Продажи Ozon'!$C$2:$C$2000="ABC-LDR-034") * ('Продажи Ozon'!$G$2:$G$2000="N") * 'Продажи Ozon'!$D$2:$D$2000 * 'Продажи Ozon'!$E$2:$E$2000),2) | F4: =ROUND(-SUMPRODUCT(('Продажи Ozon'!$C$2:$C$2000="ABC-LDR-034") * ('Продажи Ozon'!$G$2:$G$2000="Y") * 'Продажи Ozon'!$D$2:$D$2000 * 'Продажи Ozon'!$E$2:$E$2000),2) | G4: =E4-F4 | H4: =ROUND(D4 * SUMPRODUCT(('Производство'!$C$2:$C$2000="ABC-LDR-034") * 'Производство'!$E$2:$E$2000 * 'Производство'!$G$2:$G$2000) / SUMIFS('Производство'!$E:$E, 'Производство'!$C:$C, "ABC-LDR-034"),2) | I4: =ROUND(G4 * VLOOKUP("ABC-LDR-034", 'Тарифы Ozon'!$A:$E, 4, FALSE),2) | J4: =ROUND(D4 * VLOOKUP("ABC-LDR-034", 'Тарифы Ozon'!$A:$E, 5, FALSE),2) | K4: 0 | L4: =ROUND(SUMIFS('Реклама Ozon'!$D:$D, 'Реклама Ozon'!$C:$C, "ABC-LDR-034"),2) | M4: =ROUND(G4 * SUMPRODUCT(('Соинвест Ozon'!$C$2:$C$100="ABC-LDR-034") * 'Соинвест Ozon'!$E$2:$E$100 * ('Соинвест Ozon'!$B$2:$B$100-'Соинвест Ozon'!$A$2:$A$100+1)) / SUMPRODUCT(('Соинвест Ozon'!$C$2:$C$100="ABC-LDR-034") * ('Соинвест Ozon'!$B$2:$B$100-'Соинвест Ozon'!$A$2:$A$100+1)),2)
A5: ABC-LDR-034 | B5: WB | C5: Бытхимия | D5: =SUMIFS('Продажи WB'!$E:$E, 'Продажи WB'!$C:$C, "ABC-LDR-034", 'Продажи WB'!$H:$H, "N") | E5: =ROUND(SUMPRODUCT(('Продажи WB'!$C$2:$C$2000="ABC-LDR-034") * ('Продажи WB'!$H$2:$H$2000="N") * 'Продажи WB'!$E$2:$E$2000 * 'Продажи WB'!$F$2:$F$2000),2) | F5: =ROUND(-SUMPRODUCT(('Продажи WB'!$C$2:$C$2000="ABC-LDR-034") * ('Продажи WB'!$H$2:$H$2000="Y") * 'Продажи WB'!$E$2:$E$2000 * 'Продажи WB'!$F$2:$F$2000),2) | G5: =E5-F5 | H5: =ROUND(D5 * SUMPRODUCT(('Производство'!$C$2:$C$2000="ABC-LDR-034") * 'Производство'!$E$2:$E$2000 * 'Производство'!$G$2:$G$2000) / SUMIFS('Производство'!$E:$E, 'Производство'!$C:$C, "ABC-LDR-034"),2) | I5: =ROUND(G5 * VLOOKUP("ABC-LDR-034", 'Тарифы WB'!$A:$E, 4, FALSE),2) | J5: =ROUND(D5 * VLOOKUP("ABC-LDR-034", 'Тарифы WB'!$A:$E, 5, FALSE),2) | K5: 0 | L5: =ROUND(SUMIFS('Реклама WB'!$D:$D, 'Реклама WB'!$C:$C, "ABC-LDR-034"),2) | M5: 0
A6: ABC-LDR-027 | B6: Ozon | C6: Бытхимия | D6: =SUMIFS('Продажи Ozon'!$D:$D, 'Продажи Ozon'!$C:$C, "ABC-LDR-027", 'Продажи Ozon'!$G:$G, "N") | E6: =ROUND(SUMPRODUCT(('Продажи Ozon'!$C$2:$C$2000="ABC-LDR-027") * ('Продажи Ozon'!$G$2:$G$2000="N") * 'Продажи Ozon'!$D$2:$D$2000 * 'Продажи Ozon'!$E$2:$E$2000),2) | F6: =ROUND(-SUMPRODUCT(('Продажи Ozon'!$C$2:$C$2000="ABC-LDR-027") * ('Продажи Ozon'!$G$2:$G$2000="Y") * 'Продажи Ozon'!$D$2:$D$2000 * 'Продажи Ozon'!$E$2:$E$2000),2) | G6: =E6-F6 | H6: =ROUND(D6 * SUMPRODUCT(('Производство'!$C$2:$C$2000="ABC-LDR-027") * 'Производство'!$E$2:$E$2000 * 'Производство'!$G$2:$G$2000) / SUMIFS('Производство'!$E:$E, 'Производство'!$C:$C, "ABC-LDR-027"),2) | I6: =ROUND(G6 * VLOOKUP("ABC-LDR-027", 'Тарифы Ozon'!$A:$E, 4, FALSE),2) | J6: =ROUND(D6 * VLOOKUP("ABC-LDR-027", 'Тарифы Ozon'!$A:$E, 5, FALSE),2) | K6: 0 | L6: =ROUND(SUMIFS('Реклама Ozon'!$D:$D, 'Реклама Ozon'!$C:$C, "ABC-LDR-027"),2) | M6: =ROUND(G6 * SUMPRODUCT(('Соинвест Ozon'!$C$2:$C$100="ABC-LDR-027") * 'Соинвест Ozon'!$E$2:$E$100 * ('Соинвест Ozon'!$B$2:$B$100-'Соинвест Ozon'!$A$2:$A$100+1)) / SUMPRODUCT(('Соинвест Ozon'!$C$2:$C$100="ABC-LDR-027") * ('Соинвест Ozon'!$B$2:$B$100-'Соинвест Ozon'!$A$2:$A$100+1)),2)
A7: ABC-LDR-027 | B7: WB | C7: Бытхимия | D7: =SUMIFS('Продажи WB'!$E:$E, 'Продажи WB'!$C:$C, "ABC-LDR-027", 'Продажи WB'!$H:$H, "N") | E7: =ROUND(SUMPRODUCT(('Продажи WB'!$C$2:$C$2000="ABC-LDR-027") * ('Продажи WB'!$H$2:$H$2000="N") * 'Продажи WB'!$E$2:$E$2000 * 'Продажи WB'!$F$2:$F$2000),2) | F7: =ROUND(-SUMPRODUCT(('Продажи WB'!$C$2:$C$2000="ABC-LDR-027") * ('Продажи WB'!$H$2:$H$2000="Y") * 'Продажи WB'!$E$2:$E$2000 * 'Продажи WB'!$F$2:$F$2000),2) | G7: =E7-F7 | H7: =ROUND(D7 * SUMPRODUCT(('Производство'!$C$2:$C$2000="ABC-LDR-027") * 'Производство'!$E$2:$E$2000 * 'Производство'!$G$2:$G$2000) / SUMIFS('Производство'!$E:$E, 'Производство'!$C:$C, "ABC-LDR-027"),2) | I7: =ROUND(G7 * VLOOKUP("ABC-LDR-027", 'Тарифы WB'!$A:$E, 4, FALSE),2) | J7: =ROUND(D7 * VLOOKUP("ABC-LDR-027", 'Тарифы WB'!$A:$E, 5, FALSE),2) | K7: 0 | L7: =ROUND(SUMIFS('Реклама WB'!$D:$D, 'Реклама WB'!$C:$C, "ABC-LDR-027"),2) | M7: 0
A8: ABC-DSH-018 | B8: Ozon | C8: Посуда | D8: =SUMIFS('Продажи Ozon'!$D:$D, 'Продажи Ozon'!$C:$C, "ABC-DSH-018", 'Продажи Ozon'!$G:$G, "N") | E8: =ROUND(SUMPRODUCT(('Продажи Ozon'!$C$2:$C$2000="ABC-DSH-018") * ('Продажи Ozon'!$G$2:$G$2000="N") * 'Продажи Ozon'!$D$2:$D$2000 * 'Продажи Ozon'!$E$2:$E$2000),2) | F8: =ROUND(-SUMPRODUCT(('Продажи Ozon'!$C$2:$C$2000="ABC-DSH-018") * ('Продажи Ozon'!$G$2:$G$2000="Y") * 'Продажи Ozon'!$D$2:$D$2000 * 'Продажи Ozon'!$E$2:$E$2000),2) | G8: =E8-F8 | H8: =ROUND(D8 * SUMPRODUCT(('Производство'!$C$2:$C$2000="ABC-DSH-018") * 'Производство'!$E$2:$E$2000 * 'Производство'!$G$2:$G$2000) / SUMIFS('Производство'!$E:$E, 'Производство'!$C:$C, "ABC-DSH-018"),2) | I8: =ROUND(G8 * VLOOKUP("ABC-DSH-018", 'Тарифы Ozon'!$A:$E, 4, FALSE),2) | J8: =ROUND(D8 * VLOOKUP("ABC-DSH-018", 'Тарифы Ozon'!$A:$E, 5, FALSE),2) | K8: 0 | L8: =ROUND(SUMIFS('Реклама Ozon'!$D:$D, 'Реклама Ozon'!$C:$C, "ABC-DSH-018"),2) | M8: =ROUND(G8 * SUMPRODUCT(('Соинвест Ozon'!$C$2:$C$100="ABC-DSH-018") * 'Соинвест Ozon'!$E$2:$E$100 * ('Соинвест Ozon'!$B$2:$B$100-'Соинвест Ozon'!$A$2:$A$100+1)) / SUMPRODUCT(('Соинвест Ozon'!$C$2:$C$100="ABC-DSH-018") * ('Соинвест Ozon'!$B$2:$B$100-'Соинвест Ozon'!$A$2:$A$100+1)),2)
A9: ABC-DSH-018 | B9: WB | C9: Посуда | D9: =SUMIFS('Продажи WB'!$E:$E, 'Продажи WB'!$C:$C, "ABC-DSH-018", 'Продажи WB'!$H:$H, "N") | E9: =ROUND(SUMPRODUCT(('Продажи WB'!$C$2:$C$2000="ABC-DSH-018") * ('Продажи WB'!$H$2:$H$2000="N") * 'Продажи WB'!$E$2:$E$2000 * 'Продажи WB'!$F$2:$F$2000),2) | F9: =ROUND(-SUMPRODUCT(('Продажи WB'!$C$2:$C$2000="ABC-DSH-018") * ('Продажи WB'!$H$2:$H$2000="Y") * 'Продажи WB'!$E$2:$E$2000 * 'Продажи WB'!$F$2:$F$2000),2) | G9: =E9-F9 | H9: =ROUND(D9 * SUMPRODUCT(('Производство'!$C$2:$C$2000="ABC-DSH-018") * 'Производство'!$E$2:$E$2000 * 'Производство'!$G$2:$G$2000) / SUMIFS('Производство'!$E:$E, 'Производство'!$C:$C, "ABC-DSH-018"),2) | I9: =ROUND(G9 * VLOOKUP("ABC-DSH-018", 'Тарифы WB'!$A:$E, 4, FALSE),2) | J9: =ROUND(D9 * VLOOKUP("ABC-DSH-018", 'Тарифы WB'!$A:$E, 5, FALSE),2) | K9: 0 | L9: =ROUND(SUMIFS('Реклама WB'!$D:$D, 'Реклама WB'!$C:$C, "ABC-DSH-018"),2) | M9: 0
A10: ABC-KIT-051 | B10: Ozon | C10: Посуда | D10: =SUMIFS('Продажи Ozon'!$D:$D, 'Продажи Ozon'!$C:$C, "ABC-KIT-051", 'Продажи Ozon'!$G:$G, "N") | E10: =ROUND(SUMPRODUCT(('Продажи Ozon'!$C$2:$C$2000="ABC-KIT-051") * ('Продажи Ozon'!$G$2:$G$2000="N") * 'Продажи Ozon'!$D$2:$D$2000 * 'Продажи Ozon'!$E$2:$E$2000),2) | F10: =ROUND(-SUMPRODUCT(('Продажи Ozon'!$C$2:$C$2000="ABC-KIT-051") * ('Продажи Ozon'!$G$2:$G$2000="Y") * 'Продажи Ozon'!$D$2:$D$2000 * 'Продажи Ozon'!$E$2:$E$2000),2) | G10: =E10-F10 | H10: =ROUND(D10 * SUMPRODUCT(('Производство'!$C$2:$C$2000="ABC-KIT-051") * 'Производство'!$E$2:$E$2000 * 'Производство'!$G$2:$G$2000) / SUMIFS('Производство'!$E:$E, 'Производство'!$C:$C, "ABC-KIT-051"),2) | I10: =ROUND(G10 * VLOOKUP("ABC-KIT-051", 'Тарифы Ozon'!$A:$E, 4, FALSE),2) | J10: =ROUND(D10 * VLOOKUP("ABC-KIT-051", 'Тарифы Ozon'!$A:$E, 5, FALSE),2) | K10: 0 | L10: =ROUND(SUMIFS('Реклама Ozon'!$D:$D, 'Реклама Ozon'!$C:$C, "ABC-KIT-051"),2) | M10: =ROUND(G10 * SUMPRODUCT(('Соинвест Ozon'!$C$2:$C$100="ABC-KIT-051") * 'Соинвест Ozon'!$E$2:$E$100 * ('Соинвест Ozon'!$B$2:$B$100-'Соинвест Ozon'!$A$2:$A$100+1)) / SUMPRODUCT(('Соинвест Ozon'!$C$2:$C$100="ABC-KIT-051") * ('Соинвест Ozon'!$B$2:$B$100-'Соинвест Ozon'!$A$2:$A$100+1)),2)
A11: ABC-KIT-051 | B11: WB | C11: Посуда | D11: =SUMIFS('Продажи WB'!$E:$E, 'Продажи WB'!$D:$D, "Чистящий крем кухня 750 мл", 'Продажи WB'!$H:$H, "N") | E11: =ROUND(SUMPRODUCT(('Продажи WB'!$D$2:$D$2000="Чистящий крем кухня 750 мл") * ('Продажи WB'!$H$2:$H$2000="N") * 'Продажи WB'!$E$2:$E$2000 * 'Продажи WB'!$F$2:$F$2000),2) | F11: =ROUND(-SUMPRODUCT(('Продажи WB'!$D$2:$D$2000="Чистящий крем кухня 750 мл") * ('Продажи WB'!$H$2:$H$2000="Y") * 'Продажи WB'!$E$2:$E$2000 * 'Продажи WB'!$F$2:$F$2000),2) | G11: =E11-F11 | H11: =ROUND(D11 * SUMPRODUCT(('Производство'!$C$2:$C$2000="ABC-KIT-051") * 'Производство'!$E$2:$E$2000 * 'Производство'!$G$2:$G$2000) / SUMIFS('Производство'!$E:$E, 'Производство'!$C:$C, "ABC-KIT-051"),2) | I11: =ROUND(G11 * VLOOKUP("ABC-KIT-051", 'Тарифы WB'!$A:$E, 4, FALSE),2) | J11: =ROUND(D11 * VLOOKUP("ABC-KIT-051", 'Тарифы WB'!$A:$E, 5, FALSE),2) | K11: 0 | L11: =ROUND(SUMIFS('Реклама WB'!$D:$D, 'Реклама WB'!$C:$C, "ABC-KIT-051"),2) | M11: 0
A12: ABC-WND-009 | B12: Ozon | C12: Стёкла | D12: =SUMIFS('Продажи Ozon'!$D:$D, 'Продажи Ozon'!$C:$C, "ABC-WND-009", 'Продажи Ozon'!$G:$G, "N") | E12: =ROUND(SUMPRODUCT(('Продажи Ozon'!$C$2:$C$2000="ABC-WND-009") * ('Продажи Ozon'!$G$2:$G$2000="N") * 'Продажи Ozon'!$D$2:$D$2000 * 'Продажи Ozon'!$E$2:$E$2000),2) | F12: =ROUND(-SUMPRODUCT(('Продажи Ozon'!$C$2:$C$2000="ABC-WND-009") * ('Продажи Ozon'!$G$2:$G$2000="Y") * 'Продажи Ozon'!$D$2:$D$2000 * 'Продажи Ozon'!$E$2:$E$2000),2) | G12: =E12-F12 | H12: =ROUND(D12 * SUMPRODUCT(('Производство'!$C$2:$C$2000="ABC-WND-009") * 'Производство'!$E$2:$E$2000 * 'Производство'!$G$2:$G$2000) / SUMIFS('Производство'!$E:$E, 'Производство'!$C:$C, "ABC-WND-009"),2) | I12: =ROUND(G12 * VLOOKUP("ABC-WND-009", 'Тарифы Ozon'!$A:$E, 4, FALSE),2) | J12: =ROUND(D12 * VLOOKUP("ABC-WND-009", 'Тарифы Ozon'!$A:$E, 5, FALSE),2) | K12: 0 | L12: =ROUND(SUMIFS('Реклама Ozon'!$D:$D, 'Реклама Ozon'!$C:$C, "ABC-WND-009"),2) | M12: =ROUND(G12 * SUMPRODUCT(('Соинвест Ozon'!$C$2:$C$100="ABC-WND-009") * 'Соинвест Ozon'!$E$2:$E$100 * ('Соинвест Ozon'!$B$2:$B$100-'Соинвест Ozon'!$A$2:$A$100+1)) / SUMPRODUCT(('Соинвест Ozon'!$C$2:$C$100="ABC-WND-009") * ('Соинвест Ozon'!$B$2:$B$100-'Соинвест Ozon'!$A$2:$A$100+1)),2)
A13: ABC-WND-009 | B13: WB | C13: Стёкла | D13: =SUMIFS('Продажи WB'!$E:$E, 'Продажи WB'!$C:$C, "WND-009", 'Продажи WB'!$H:$H, "N") | E13: =ROUND(SUMPRODUCT(('Продажи WB'!$C$2:$C$2000="WND-009") * ('Продажи WB'!$H$2:$H$2000="N") * 'Продажи WB'!$E$2:$E$2000 * 'Продажи WB'!$F$2:$F$2000),2) | F13: =ROUND(-SUMPRODUCT(('Продажи WB'!$C$2:$C$2000="WND-009") * ('Продажи WB'!$H$2:$H$2000="Y") * 'Продажи WB'!$E$2:$E$2000 * 'Продажи WB'!$F$2:$F$2000),2) | G13: =E13-F13 | H13: =ROUND(D13 * SUMPRODUCT(('Производство'!$C$2:$C$2000="ABC-WND-009") * 'Производство'!$E$2:$E$2000 * 'Производство'!$G$2:$G$2000) / SUMIFS('Производство'!$E:$E, 'Производство'!$C:$C, "ABC-WND-009"),2) | I13: =ROUND(G13 * VLOOKUP("ABC-WND-009", 'Тарифы WB'!$A:$E, 4, FALSE),2) | J13: =ROUND(D13 * VLOOKUP("ABC-WND-009", 'Тарифы WB'!$A:$E, 5, FALSE),2) | K13: 0 | L13: =ROUND(SUMIFS('Реклама WB'!$D:$D, 'Реклама WB'!$C:$C, "ABC-WND-009"),2) | M13: 0

Sheet Валовая
A1: SKU | B1: Канал | C1: Категория | D1: Чистая выручка, ₽ | E1: Себестоимость, ₽ | F1: Валовая прибыль, ₽
A2: =Источники!A2 | B2: =Источники!B2 | C2: =Источники!C2 | D2: =Источники!G2 | E2: =Источники!H2 | F2: =D2-E2
A3: =Источники!A3 | B3: =Источники!B3 | C3: =Источники!C3 | D3: =Источники!G3 | E3: =Источники!H3 | F3: =D3-E3
A4: =Источники!A4 | B4: =Источники!B4 | C4: =Источники!C4 | D4: =Источники!G4 | E4: =Источники!H4 | F4: =D4-E4
A5: =Источники!A5 | B5: =Источники!B5 | C5: =Источники!C5 | D5: =Источники!G5 | E5: =Источники!H5 | F5: =D5-E5
A6: =Источники!A6 | B6: =Источники!B6 | C6: =Источники!C6 | D6: =Источники!G6 | E6: =Источники!H6 | F6: =D6-E6
A7: =Источники!A7 | B7: =Источники!B7 | C7: =Источники!C7 | D7: =Источники!G7 | E7: =Источники!H7 | F7: =D7-E7
A8: =Источники!A8 | B8: =Источники!B8 | C8: =Источники!C8 | D8: =Источники!G8 | E8: =Источники!H8 | F8: =D8-E8
A9: =Источники!A9 | B9: =Источники!B9 | C9: =Источники!C9 | D9: =Источники!G9 | E9: =Источники!H9 | F9: =D9-E9
A10: =Источники!A10 | B10: =Источники!B10 | C10: =Источники!C10 | D10: =Источники!G10 | E10: =Источники!H10 | F10: =D10-E10
A11: =Источники!A11 | B11: =Источники!B11 | C11: =Источники!C11 | D11: =Источники!G11 | E11: =Источники!H11 | F11: =D11-E11
A12: =Источники!A12 | B12: =Источники!B12 | C12: =Источники!C12 | D12: =Источники!G12 | E12: =Источники!H12 | F12: =D12-E12
A13: =Источники!A13 | B13: =Источники!B13 | C13: =Источники!C13 | D13: =Источники!G13 | E13: =Источники!H13 | F13: =D13-E13

Sheet Маржинальная
A1: SKU | B1: Канал | C1: Категория | D1: Валовая прибыль, ₽ | E1: Комиссия, ₽ | F1: Логистика, ₽ | G1: Эквайринг, ₽ | H1: ДРР, ₽ | I1: Соинвест, ₽ | J1: Маржинальная прибыль, ₽
A2: =Валовая!A2 | B2: =Валовая!B2 | C2: =Валовая!C2 | D2: =Валовая!F2 | E2: =Источники!I2 | F2: =Источники!J2 | G2: =Источники!K2 | H2: =Источники!L2 | I2: =Источники!M2 | J2: =D2-E2-F2-G2-H2+I2
A3: =Валовая!A3 | B3: =Валовая!B3 | C3: =Валовая!C3 | D3: =Валовая!F3 | E3: =Источники!I3 | F3: =Источники!J3 | G3: =Источники!K3 | H3: =Источники!L3 | I3: =Источники!M3 | J3: =D3-E3-F3-G3-H3+I3
A4: =Валовая!A4 | B4: =Валовая!B4 | C4: =Валовая!C4 | D4: =Валовая!F4 | E4: =Источники!I4 | F4: =Источники!J4 | G4: =Источники!K4 | H4: =Источники!L4 | I4: =Источники!M4 | J4: =D4-E4-F4-G4-H4+I4
A5: =Валовая!A5 | B5: =Валовая!B5 | C5: =Валовая!C5 | D5: =Валовая!F5 | E5: =Источники!I5 | F5: =Источники!J5 | G5: =Источники!K5 | H5: =Источники!L5 | I5: =Источники!M5 | J5: =D5-E5-F5-G5-H5+I5
A6: =Валовая!A6 | B6: =Валовая!B6 | C6: =Валовая!C6 | D6: =Валовая!F6 | E6: =Источники!I6 | F6: =Источники!J6 | G6: =Источники!K6 | H6: =Источники!L6 | I6: =Источники!M6 | J6: =D6-E6-F6-G6-H6+I6
A7: =Валовая!A7 | B7: =Валовая!B7 | C7: =Валовая!C7 | D7: =Валовая!F7 | E7: =Источники!I7 | F7: =Источники!J7 | G7: =Источники!K7 | H7: =Источники!L7 | I7: =Источники!M7 | J7: =D7-E7-F7-G7-H7+I7
A8: =Валовая!A8 | B8: =Валовая!B8 | C8: =Валовая!C8 | D8: =Валовая!F8 | E8: =Источники!I8 | F8: =Источники!J8 | G8: =Источники!K8 | H8: =Источники!L8 | I8: =Источники!M8 | J8: =D8-E8-F8-G8-H8+I8
A9: =Валовая!A9 | B9: =Валовая!B9 | C9: =Валовая!C9 | D9: =Валовая!F9 | E9: =Источники!I9 | F9: =Источники!J9 | G9: =Источники!K9 | H9: =Источники!L9 | I9: =Источники!M9 | J9: =D9-E9-F9-G9-H9+I9
A10: =Валовая!A10 | B10: =Валовая!B10 | C10: =Валовая!C10 | D10: =Валовая!F10 | E10: =Источники!I10 | F10: =Источники!J10 | G10: =Источники!K10 | H10: =Источники!L10 | I10: =Источники!M10 | J10: =D10-E10-F10-G10-H10+I10
A11: =Валовая!A11 | B11: =Валовая!B11 | C11: =Валовая!C11 | D11: =Валовая!F11 | E11: =Источники!I11 | F11: =Источники!J11 | G11: =Источники!K11 | H11: =Источники!L11 | I11: =Источники!M11 | J11: =D11-E11-F11-G11-H11+I11
A12: =Валовая!A12 | B12: =Валовая!B12 | C12: =Валовая!C12 | D12: =Валовая!F12 | E12: =Источники!I12 | F12: =Источники!J12 | G12: =Источники!K12 | H12: =Источники!L12 | I12: =Источники!M12 | J12: =D12-E12-F12-G12-H12+I12
A13: =Валовая!A13 | B13: =Валовая!B13 | C13: =Валовая!C13 | D13: =Валовая!F13 | E13: =Источники!I13 | F13: =Источники!J13 | G13: =Источники!K13 | H13: =Источники!L13 | I13: =Источники!M13 | J13: =D13-E13-F13-G13-H13+I13

Sheet Постоянные
A1: Статья | B1: Сумма, ₽
A2: Зарплата | B2: =SUM('Зарплатная ведомость'!$G:$G)
A3: Аренда | B3: =SUMIFS('Прочие постоянные'!$E:$E, 'Прочие постоянные'!$D:$D, "Аренда")
A4: IT-услуги | B4: =SUMIFS('Прочие постоянные'!$E:$E, 'Прочие постоянные'!$D:$D, "IT-услуги")
A5: Прочие услуги | B5: =SUMIFS('Прочие постоянные'!$E:$E, 'Прочие постоянные'!$D:$D, "Прочие услуги")
A6: Прочие административные | B6: =SUMIFS('Прочие постоянные'!$E:$E, 'Прочие постоянные'!$D:$D, "Прочие административные")
A7: ИТОГО | B7: =SUM(B2:B6)

Sheet Операционная
A1: Категория | B1: Чистая выручка, ₽ | C1: Маржинальная прибыль, ₽ | D1: Доля выручки | E1: Постоянные (alloc), ₽ | F1: Бренд (alloc), ₽ | G1: EBITDA, ₽ | H1: EBITDA, %
A2: Бытхимия | B2: =SUMIFS(Валовая!$D:$D, Валовая!$C:$C, "Бытхимия") | C2: =SUMIFS(Маржинальная!$J:$J, Маржинальная!$C:$C, "Бытхимия") | D2: =B2/SUM($B$2:$B$4) | E2: =D2*Постоянные!$B$7 | F2: =D2*800000 | G2: =C2-E2-F2 | H2: =G2/B2
A3: Посуда | B3: =SUMIFS(Валовая!$D:$D, Валовая!$C:$C, "Посуда") | C3: =SUMIFS(Маржинальная!$J:$J, Маржинальная!$C:$C, "Посуда") | D3: =B3/SUM($B$2:$B$4) | E3: =D3*Постоянные!$B$7 | F3: =D3*800000 | G3: =C3-E3-F3 | H3: =G3/B3
A4: Стёкла | B4: =SUMIFS(Валовая!$D:$D, Валовая!$C:$C, "Стёкла") | C4: =SUMIFS(Маржинальная!$J:$J, Маржинальная!$C:$C, "Стёкла") | D4: =B4/SUM($B$2:$B$4) | E4: =D4*Постоянные!$B$7 | F4: =D4*800000 | G4: =C4-E4-F4 | H4: =G4/B4
A5: ИТОГО | B5: =SUM(B2:B4) | C5: =SUM(C2:C4) | D5: =SUM(D2:D4) | E5: =SUM(E2:E4) | F5: =SUM(F2:F4) | G5: =SUM(G2:G4) | H5: =G5/B5

Sheet Свод
A1: Уровень | B1: Сумма, ₽ | C1: % от чистой выручки
A2: Чистая выручка | B2: =Операционная!B5 | C2: 1
A3: Маржинальная прибыль | B3: =Операционная!C5 | C3: =B3/B$2
A4: (−) Постоянные | B4: =-Операционная!E5 | C4: =B4/B$2
A5: (−) Бренд-маркетинг | B5: =-Операционная!F5 | C5: =B5/B$2
A6: EBITDA | B6: =Операционная!G5 | C6: =Операционная!H5
